Workbook

Sheet Léeme
A1: Modelo de presupuesto — Hugo y Dogo (N Club · Sabana Hack 2026)
A3: Cómo usar este archivo
A4: 1. Edite solo la hoja 'Supuestos' (y las celdas azules de 'A_Prototipo' y de la tabla de escalamiento en 'Resumen'). Todo lo demás se calcula solo.
A5: 2. Celdas en texto AZUL = datos de entrada. Celdas con fondo AMARILLO = supuestos clave; se recomienda reemplazarlos por cotizaciones cuando estén disponibles.
A6: 3. Texto NEGRO = fórmulas. Texto VERDE = vínculos a otra hoja. No sobrescriba esas celdas.
A7: 4. Cada concepto tiene tres escenarios: Bajo, Base y Alto. El escenario Base es la referencia de la propuesta.
A9: Estructura
A10: Supuestos — todos los insumos con su fuente o la marca 'Supuesto del equipo'.
A11: Resumen — cifras clave por escenario, alternativa Robots-as-a-Service y escalamiento de la flota.
A12: A_Prototipo — lo que costó el prototipo en la Sabana Hack (valor de referencia vs. costo en caja). Los robots prestados no hacen gratis el despliegue.
A13: B_Inversion — inversión inicial (CAPEX) para llevar Hugo y Dogo a producción en N Club.
A14: C_Operacion — costo anual de operación (OPEX).
... A28: Solo los precios de hardware, la TRM y el IVA tienen fuente pública. El resto son supuestos del equipo para presentar con rango, no cotizaciones.

Sheet Resumen
A1: Resumen — Presupuesto Hugo y Dogo para N Club
A2: Sede única de N Club. Configuración de referencia: 1 humanoide AgiBot X2 y 1 cuadrúpedo AgiBot D1 Edu.
A4: Cifra clave | B4: Unidad | C4: Bajo | D4: Base | E4: Alto | F4: Nota
A5: Prototipo hackathon — valor de referencia usado | B5: USD | C5: =A_Prototipo!$B$16 -> 36778.398 | D5: =A_Prototipo!$B$16 -> 36778.398 | E5: =A_Prototipo!$B$16 -> 36778.398 | F5: Costo en caja ≈ 0: robots prestados, créditos estudiantiles.
A6: Inversión inicial (CAPEX) | B6: USD | C6: =B_Inversion!C23 -> 70296.494 | D6: =B_Inversion!D23 -> 114880.76 | E6: =B_Inversion!E23 -> 222153.17 | F6: Hardware, importación, desarrollo, puesta en marcha y contingencia.
A7: Operación anual (OPEX) | B7: USD / año | C7: =C_Operacion!C14 -> 13302.851 | D7: =C_Operacion!D14 -> 32587.836 | E7: =C_Operacion!E14 -> 77002.691 | F7: Nube, IA, mantenimiento, soporte, supervisión y seguro.
A8: Costo mensual amortizado | B8: USD / mes | C8: =B_Inversion!C23/Supuestos!$C$9+C_Operacion!C14/12 -> 3061.2513 | D8: =B_Inversion!D23/Supuestos!$D$9+C_Operacion!D14/12 -> 5906.7852 | E8: =B_Inversion!E23/Supuestos!$E$9+C_Operacion!E14/12 -> 12587.812 | F8: Inversión ÷ vida útil + operación ÷ 12.
A9: Costo total de propiedad a 3 años (TCO) | B9: USD | C9: =B_Inversion!C23+3*C_Operacion!C14 -> 110205.05 | D9: =B_Inversion!D23+3*C_Operacion!D14 -> 212644.27 | E9: =B_Inversion!E23+3*C_Operacion!E14 -> 453161.24 | F9: Inversión + 3 años de operación.
A10: Alternativa a explorar: mensualidad Robots-as-a-Service | B10: USD / mes | C10: =C8*(1+Supuestos!$C$45) -> 3673.5015 | D10: =D8*(1+Supuestos!$D$45) -> 7383.4815 | E10: =E8*(1+Supuestos!$E$45) -> 16364.156 | F10: Opcional: arrendamiento para evitar la inversión inicial. No es el modelo principal.
A11: Costo por interacción atendida | B11: USD | C11: =Valor_Impacto!C10 -> 1.4717554 | D11: =Valor_Impacto!D10 -> 1.8932004 | E11: =Valor_Impacto!E10 -> 2.6224609 | F11: Hipótesis de volumen por validar.
A12: Equivalente en pesos colombianos
A13: Inversión inicial (CAPEX) | B13: COP millones | C13: =C6*Supuestos!$C$6/1000000 -> 222.40124 | D13: =D6*Supuestos!$D$6/1000000 -> 363.45515 | E13: =E6*Supuestos!$E$6/1000000 -> 702.83932 | F13: A la TRM de 'Supuestos'.
A14: Operación anual (OPEX) | B14: COP millones / año | C14: =C7*Supuestos!$C$6/1000000 -> 42.087026 | D14: =D7*Supuestos!$D$6/1000000 -> 103.10009 | E14: =E7*Supuestos!$E$6/1000000 -> 243.61803
A15: Costo mensual amortizado | B15: COP millones / mes | C15: =C8*Supuestos!$C$6/1000000 -> 9.6850643 | D15: =D8*Supuestos!$D$6/1000000 -> 18.687651 | E15: =E8*Supuestos!$E$6/1000000 -> 39.824817
A17: Escalamiento de la flota en N Club (escenario Base)
A18: El club tiene una sola sede: escalar significa sumar robots según la demanda. Edite las cantidades en azul.
A19: Configuración | B19: Humanoides X2 | C19: Cuadrúpedos D1 | D19: Inversión inicial (USD) | E19: Operación anual (USD) | F19: Costo mensual (USD) | G19: TCO 3 años (USD)
A20: Referencia: recepción + acompañamiento | B20: 1 | C20: 1 | D20: =B_Inversion!$D$28+B20*B_Inversion!$D$26+C20*B_Inversion!$D$27 -> 114880.76 | E20: =C_Operacion!$D$19+B20*C_Operacion!$D$17+C20*C_Operacion!$D$18 -> 32587.836 | F20: =D20/Supuestos!$D$9+E20/12 -> 5906.7852 | G20: =D20+3*E20 -> 212644.27
A21: Más acompañamientos simultáneos | B21: 1 | C21: 2 | D21: =B_Inversion!$D$28+B21*B_Inversion!$D$26+C21*B_Inversion!$D$27 -> 125482.19 | E21: =C_Operacion!$D$19+B21*C_Operacion!$D$17+C21*C_Operacion!$D$18 -> 33834.179 | F21: =D21/Supuestos!$D$9+E21/12 -> 6305.1312 | G21: =D21+3*E21 -> 226984.72
A22: Segundo punto de atención (p. ej. acceso de personal y externos) | B22: 2 | C22: 2 | D22: =B_Inversion!$D$28+B22*B_Inversion!$D$26+C22*B_Inversion!$D$27 -> 168921.68 | E22: =C_Operacion!$D$19+B22*C_Operacion!$D$17+C22*C_Operacion!$D$18 -> 40617.614 | F22: =D22/Supuestos!$D$9+E22/12 -> 8077.07 | G22: =D22+3*E22 -> 290774.52
A23: Cobertura ampliada en eventos y horas pico | B23: 2 | C23: 3 | D23: =B_Inversion!$D$28+B23*B_Inversion!$D$26+C23*B_Inversion!$D$27 -> 179523.11 | E23: =C_Operacion!$D$19+B23*C_Operacion!$D$17+C23*C_Operacion!$D$18 -> 41863.956 | F23: =D23/Supuestos!$D$9+E23/12 -> 8475.416 | G23: =D23+3*E23 -> 305114.98
A24: Lectura: desarrollo, integración, privacidad y soporte se pagan una sola vez; cada robot adicional solo suma su hardware, importación, mantenimiento y seguro. Un D1 extra es la forma más barata de crecer.

Sheet Analisis_Financiero
A1: Análisis financiero — N Club compra e implementa Hugo y Dogo
A2: Costos en escenario Base. Beneficios en tres escenarios (Conservador / Base / Optimista): son hipótesis de demostración por validar en el piloto, NO datos medidos de N Club.
A4: 1. Costo para el club (escenario Base de costos)
A5: Inversión inicial | B5: USD | C5: =B_Inversion!$D$23 -> 114880.76
A6: Operación anual | B6: USD / año | C6: =C_Operacion!$D$14 -> 32587.836
A7: Operación mensual | B7: USD / mes | C7: =C_Operacion!$D$14/12 -> 2715.653
A8: Costo total de propiedad a 3 años | B8: USD | C8: =B_Inversion!$D$23+3*C_Operacion!$D$14 -> 212644.27
A10: 2. Retorno objetivo: ¿cuánto valor mensual debe generar para recuperarse?
A11: Plazo para recuperar la inversión | B11: Meses | C11: Valor mensual necesario (USD) | D11: Equivalente (COP millones / mes) | F11: Cálculo
A12: Recuperar en 2 años | B12: 24 | C12: =C5/B12+C7 -> 7502.3513 | D12: =C12*Supuestos!$D$6/1000000 -> 23.735639 | F12: inversión ÷ meses + operación mensual
A13: Recuperar en 3 años | B13: 36 | C13: =C5/B13+C7 -> 5906.7852 | D13: =C13*Supuestos!$D$6/1000000 -> 18.687651 | F13: inversión ÷ meses + operación mensual
A14: Recuperar en 4 años | B14: 48 | C14: =C5/B14+C7 -> 5109.0022 | D14: =C14*Supuestos!$D$6/1000000 -> 16.163657 | F14: inversión ÷ meses + operación mensual
A16: 3. Fuentes de valor (hipótesis por validar en el piloto)
A17: Supuesto | B17: Unidad | C17: Conservador | D17: Base | E17: Optimista | F17: Nota
A18: Reservas sugeridas por el robot (flujos VIP y regular)
A19: Reservas adicionales que generan Hugo y Dogo | B19: reservas / día | C19: 2 | D19: 4 | E19: 6 | F19: Supuesto del equipo — dato de demostración, validar con N Club. Reservas que no ocurrirían sin la sugerencia activa del robot.
A20: Ticket promedio por reserva (restaurante, spa, golf) | B20: COP | C20: 120000 | D20: 150000 | E20: 200000 | F20: Supuesto del equipo — dato de demostración, validar con N Club.
A21: Margen de contribución de la reserva | B21: % | C21: 0.3 | D21: 0.35 | E21: 0.4 | F21: Supuesto del equipo — dato de demostración, validar con N Club.
A22: Retención de miembros por mejor experiencia
A23: Membresías que se dejan de perder | B23: membresías / año | C23: 1 | D23: 2 | E23: 3 | F23: Supuesto del equipo — dato de demostración, validar con N Club.
A24: Cuota mensual de sostenimiento | B24: COP / mes | C24: 1500000 | D24: 2000000 | E24: 2500000 | F24: Supuesto del equipo — dato de demostración, validar con N Club. Cada membresía retenida aporta su cuota mensual.
A25: Tiempo del personal en inicio de jornada
A26: Empleados que reciben novedades del robot | B26: empleados / día | C26: 30 | D26: 40 | E26: 50 | F26: Supuesto del equipo — dato de demostración, validar con N Club.
A27: Minutos ahorrados por empleado | B27: minutos | C27: 2 | D27: 3 | E27: 4 | F27: Supuesto del equipo — dato de demostración, validar con N Club. Frente a buscar al coordinador o revisar carteleras.
A28: Costo mensual cargado de un empleado | B28: COP / mes | C28: 2500000 | D28: 3000000 | E28: 3500000 | F28: Supuesto del equipo — dato de demostración, validar con N Club.
A29: Acompañamiento de trabajadores externos
A30: Trabajadores externos atendidos | B30: externos / día | C30: 3 | D30: 6 | E30: 9 | F30: Supuesto del equipo — dato de demostración, validar con N Club.
A31: Minutos de acompañamiento humano que hace el D1 | B31: minutos / externo | C31: 10 | D31: 15 | E31: 20 | F31: Supuesto del equipo — dato de demostración, validar con N Club.
A32: Parámetros financieros
A33: Tasa de descuento anual | B33: % | C33: 0.12 | D33: 0.12 | E33: 0.12 | F33: Supuesto del equipo: costo de oportunidad del capital para el club.
A35: Valor mensual por fuente | B35: Unidad | C35: Conservador | D35: Base | E35: Optimista | F35: Cálculo
A36: Margen de reservas adicionales | B36: USD / mes | C36: =C19*Supuestos!$D$34*C20*C21/Supuestos!$D$6 -> 591.70101 | D36: =D19*Supuestos!$D$34*D20*D21/Supuestos!$D$6 -> 1725.7946 | E36: =E19*Supuestos!$D$34*E20*E21/Supuestos!$D$6 -> 3944.6734 | F36: reservas/día × días × ticket × margen ÷ TRM
A37: Cuotas de membresías retenidas | B37: USD / mes | C37: =C23*C24/Supuestos!$D$6 -> 474.1194 | D37: =D23*D24/Supuestos!$D$6 -> 1264.3184 | E37: =E23*E24/Supuestos!$D$6 -> 2370.597 | F37: membresías × cuota ÷ TRM
A38: Tiempo de recepción liberado (meta 30 %) | B38: USD / mes | C38: =Valor_Impacto!C8 -> 102.72587 | D38: =Valor_Impacto!D8 -> 269.65541 | E38: =Valor_Impacto!E8 -> 632.1592 | F38: hoja Valor_Impacto
A39: Tiempo del personal en inicio de jornada | B39: USD / mes | C39: =C26*C27/60*Supuestos!$D$34*C28/Supuestos!$D$33/Supuestos!$D$6 -> 107.00612 | D39: =D26*D27/60*Supuestos!$D$34*D28/Supuestos!$D$33/Supuestos!$D$6 -> 256.81468 | E39: =E26*E27/60*Supuestos!$D$34*E28/Supuestos!$D$33/Supuestos!$D$6 -> 499.36187 | F39: empleados × min ÷ 60 × días × costo hora ÷ TRM
A40: Acompañamiento humano de externos que asume el D1 | B40: USD / mes | C40: =C30*C31/60*Supuestos!$D$34*Supuestos!$D$32/Supuestos!$D$33/Supuestos!$D$6 -> 74.904281 | D40: =D30*D31/60*Supuestos!$D$34*Supuestos!$D$32/Supuestos!$D$33/Supuestos!$D$6 -> 224.71284 | E40: =E30*E31/60*Supuestos!$D$34*Supuestos!$D$32/Supuestos!$D$33/Supuestos!$D$6 -> 449.42568 | F40: externos × min ÷ 60 × días × costo hora recepción ÷ TRM
A41: Valor mensual total | B41: USD / mes | C41: =SUM(C36:C40) -> 1350.4567 | D41: =SUM(D36:D40) -> 3741.296 | E41: =SUM(E36:E40) -> 7896.2172
A42: Cobertura del valor necesario para recuperar en 3 años | B42: % | C42: =IF($C$13=0,0,C41/$C$13) -> 0.22862803 | D42: =IF($C$13=0,0,D41/$C$13) -> 0.63338954 | E42: =IF($C$13=0,0,E41/$C$13) -> 1.3368045 | F42: valor mensual total ÷ valor necesario a 36 meses
A44: 4. Flujo de caja para el club (USD)
A45: Año | C45: Conservador | D45: Base | E45: Optimista | F45: Cálculo
...

Sheet Supuestos
A1: Supuestos del modelo
A2: Celdas azules = entradas editables. Fondo amarillo = supuesto clave a revisar o reemplazar por una cotización.
A4: Concepto | B4: Unidad | C4: Bajo | D4: Base | E4: Alto | F4: Fuente / nota
A5: Generales
A6: TRM | B6: COP por USD | C6: 3163.76 | D6: 3163.76 | E6: 3163.76 | F6: TRM oficial 21-oct-2026: COP 3.163,76 (Portafolio). Actualizar el día de la entrega.
A7: Humanoides X2 en la flota | B7: unidades | C7: 1 | D7: 1 | E7: 1 | F7: Recepción principal. Para escalar, use la tabla de escalamiento en 'Resumen'.
A8: Cuadrúpedos D1 en la flota | B8: unidades | C8: 1 | D8: 1 | E8: 1 | F8: Acompañamiento, carga y escolta.
A9: Vida útil para amortizar el CAPEX | B9: meses | C9: 36 | D9: 36 | E9: 36 | F9: Supuesto del equipo: 3 años de vida útil del hardware.
A10: Hardware (precio unitario)
A11: Humanoide AgiBot X2 | B11: USD / unidad | C11: 25600 | D11: 27999 | E11: 42999 | F11: AgiBot Store: X2 Neo USD 25.600 (store.agibot.com/products/x2). GlobalDroneHQ guía 2026: X2 USD 27.999, X2 Ultra USD 42.999. Alto = versión Ultra.
A12: Cuadrúpedo AgiBot D1 | B12: USD / unidad | C12: 6080 | D12: 7199 | E12: 7999 | F12: AgiBot Store: D1 Edu USD 6.080 (store.agibot.com/products/d1-edu). GlobalDroneHQ guía 2026: D1 Edu USD 7.199; D1 Ultra USD 7.999. Edu incluye SDK y 5 kg de carga.
A13: Baterías de repuesto por X2 | B13: unidades | C13: 0 | D13: 1 | E13: 2 | F13: Supuesto del equipo: una batería extra permite operar jornadas completas.
A14: Precio batería de repuesto | B14: USD / unidad | C14: 1499 | D14: 1499 | E14: 1499 | F14: GlobalDroneHQ guía 2026 (accesorio listado para X2 Ultra).
A15: Flete, seguro de transporte y aranceles | B15: % del hardware | C15: 0.05 | D15: 0.1 | E15: 0.15 | F15: Supuesto del equipo — POR COTIZAR con un agente de aduanas.
A16: IVA Colombia | B16: % | C16: 0.19 | D16: 0.19 | E16: 0.19 | F16: Tarifa general de IVA en Colombia.
A17: Infraestructura del club
A18: Servidor edge (reconocimiento facial e IA local) | B18: USD (único) | C18: 1500 | D18: 2500 | E18: 4000 | F18: Supuesto del equipo — se recomienda reemplazar por cotización. PC con GPU para procesar video sin enviarlo a la nube. Con más de 2 X2 podría requerir más capacidad.
A19: Red WiFi, puntos de acceso y estaciones de carga | B19: USD (único) | C19: 1000 | D19: 2000 | E19: 3500 | F19: Supuesto del equipo — se recomienda reemplazar por cotización.
A20: Desarrollo e integración (costo único)
A21: Personas en el equipo de desarrollo | B21: personas | C21: 3 | D21: 4 | E21: 5 | F21: Supuesto del equipo — se recomienda reemplazar por cotización.
A22: Duración del desarrollo hasta producción | B22: meses | C22: 3 | D22: 4 | E22: 6 | F22: Supuesto del equipo — se recomienda reemplazar por cotización. Incluye integración con membresías, invitaciones y órdenes de trabajo.
A23: Costo mensual por persona (cargado) | B23: COP / mes | C23: 6000000 | D23: 8000000 | E23: 10000000 | F23: Supuesto del equipo — se recomienda reemplazar por cotización. Ajustar a la tarifa real de mercado.
A24: Puesta en marcha
A25: Mapeo SLAM del club, geo-fencing y pruebas en sitio | B25: USD (único) | C25: 1000 | D25: 2000 | E25: 4000 | F25: Supuesto del equipo — se recomienda reemplazar por cotización.
A26: Privacidad de datos biométricos (Ley 1581) | B26: COP (único) | C26: 5000000 | D26: 10000000 | E26: 20000000 | F26: Supuesto del equipo — se recomienda reemplazar por cotización. Evaluación de impacto, consentimiento y políticas. La biometría es dato sensible.
A27: Capacitación inicial del personal | B27: COP (único) | C27: 2000000 | D27: 4000000 | E27: 6000000 | F27: Supuesto del equipo — se recomienda reemplazar por cotización.
A28: Duración del piloto | B28: meses | C28: 3 | D28: 3 | E28: 3 | F28: Piloto previo a la operación, según la propuesta.
A29: Supervisión humana durante el piloto | B29: horas / día | C29: 4 | D29: 6 | E29: 8 | F29: Supuesto del equipo — se recomienda reemplazar por cotización.
A30: Contingencia | B30: % del subtotal | C30: 0.1 | D30: 0.125 | E30: 0.15 | F30: Práctica usual en proyectos de tecnología: 10–15 %.
A31: Personal de recepción (para valorar tiempo)
A32: Costo mensual cargado de un recepcionista | B32: COP / mes | C32: 3000000 | D32: 3500000 | E32: 4000000 | F32: Supuesto del equipo — se recomienda reemplazar por cotización. Incluye prestaciones sociales.
A33: Horas laborales al mes | B33: horas | C33: 192 | D33: 192 | E33: 192 | F33: Referencia: 8 h × 24 días.
A34: Días de operación del club al mes | B34: días | C34: 26 | D34: 26 | E34: 30 | F34: Supuesto del equipo — se recomienda reemplazar por cotización.
A35: Operación anual
A36: Nube, base de datos y almacenamiento | B36: USD / mes | C36: 50 | D36: 150 | E36: 400 | F36: Supuesto del equipo — se recomienda reemplazar por cotización. En la hackathon se cubre con créditos estudiantiles.
A37: APIs de voz e IA conversacional | B37: USD / mes por X2 | C37: 50 | D37: 150 | E37: 400 | F37: Supuesto del equipo — se recomienda reemplazar por cotización. Voz a texto, texto a voz y modelo de lenguaje; crece con cada humanoide.
A38: Mantenimiento y repuestos | B38: % del hardware / año | C38: 0.08 | D38: 0.12 | E38: 0.15 | F38: Supuesto del equipo — se recomienda reemplazar por cotización.
A39: Soporte y evolución del software | B39: personas (FTE) | C39: 0.25 | D39: 0.5 | E39: 1 | F39: Supuesto del equipo — se recomienda reemplazar por cotización. Usa el costo mensual por persona de desarrollo.
A40: Supervisión humana en operación | B40: horas / día | C40: 1 | D40: 2 | E40: 3 | F40: Tiempo de recepción dedicado a excepciones ('Protocolo de Calidez ante la Duda').
A41: Seguro todo riesgo de los equipos | B41: % del hardware / año | C41: 0.015 | D41: 0.02 | E41: 0.03 | F41: Supuesto del equipo — se recomienda reemplazar por cotización.
...

Sheet A_Prototipo
A1: Bloque A — Prototipo de hackathon
A2: El costo en caja es casi cero, pero el valor de referencia muestra lo que se usó. Los robots prestados no hacen gratis el despliegue.
A4: Entradas del prototipo
A5: Integrantes del equipo | B5: 5 | D5: Equipo de 5 roles (2 Industrial, Informática, Diseño, Comunicación).
A6: Horas por integrante durante la hackathon | B6: 24 | D6: Supuesto del equipo: ajustar a las horas reales trabajadas.
A7: Costo hora de referencia (USD) | B7: =Supuestos!$D$23/Supuestos!$D$33/Supuestos!$D$6 -> 13.169983 | D7: Derivado del costo mensual por persona (escenario Base) ÷ horas al mes ÷ TRM.
A9: Concepto | B9: Valor de referencia (USD) | C9: Costo en caja (USD) | D9: Nota
A10: Humanoide AgiBot X2 (prestado por el evento) | B10: =Supuestos!$D$11 -> 27999 | C10: 0 | D10: Valor del equipo prestado (precio Base).
A11: Cuadrúpedo AgiBot D1 (prestado por el evento) | B11: =Supuestos!$D$12 -> 7199 | C11: 0 | D11: Valor del equipo prestado (precio Base).
A12: Horas del equipo | B12: =B5*B6*B7 -> 1580.398 | C12: 0 | D12: Trabajo no remunerado del equipo, valorado a tarifa de referencia.
A13: Simulador MuJoCo | B13: 0 | C13: 0 | D13: Software de código abierto recomendado por el reto.
A14: Nube, base de datos y hosting | B14: 0 | C14: 0 | D14: Créditos estudiantiles (GitHub Student Pack, Azure for Students, etc.).
A15: Alimentación y espacio de trabajo | B15: 0 | C15: 0 | D15: Provistos por la organización del evento.
A16: Total prototipo | B16: =SUM(B10:B15) -> 36778.398 | C16: =SUM(C10:C15) -> 0

Sheet B_Inversion
A1: Bloque B — Inversión inicial para llevar a producción en N Club (CAPEX, USD)
A3: Concepto | B3: Tipo | C3: Bajo | D3: Base | E3: Alto | F3: Cálculo
A4: Hardware robótico
A5: Humanoides AgiBot X2 | B5: Por robot | C5: =Supuestos!$C$7*Supuestos!$C$11 -> 25600 | D5: =Supuestos!$D$7*Supuestos!$D$11 -> 27999 | E5: =Supuestos!$E$7*Supuestos!$E$11 -> 42999 | F5: X2 en la flota × precio
A6: Cuadrúpedos AgiBot D1 | B6: Por robot | C6: =Supuestos!$C$8*Supuestos!$C$12 -> 6080 | D6: =Supuestos!$D$8*Supuestos!$D$12 -> 7199 | E6: =Supuestos!$E$8*Supuestos!$E$12 -> 7999 | F6: D1 en la flota × precio
A7: Baterías de repuesto | B7: Por robot | C7: =Supuestos!$C$7*Supuestos!$C$13*Supuestos!$C$14 -> 0 | D7: =Supuestos!$D$7*Supuestos!$D$13*Supuestos!$D$14 -> 1499 | E7: =Supuestos!$E$7*Supuestos!$E$13*Supuestos!$E$14 -> 2998 | F7: X2 × baterías por X2 × precio
A8: Subtotal robots | B8: Por robot | C8: =SUM(C5:C7) -> 31680 | D8: =SUM(D5:D7) -> 36697 | E8: =SUM(E5:E7) -> 53996 | F8: Suma
A9: Flete, seguro de transporte y aranceles | B9: Por robot | C9: =C8*Supuestos!$C$15 -> 1584 | D9: =D8*Supuestos!$D$15 -> 3669.7 | E9: =E8*Supuestos!$E$15 -> 8099.4 | F9: robots × %
A10: IVA de importación | B10: Por robot | C10: =(C8+C9)*Supuestos!$C$16 -> 6320.16 | D10: =(D8+D9)*Supuestos!$D$16 -> 7669.673 | E10: =(E8+E9)*Supuestos!$E$16 -> 11798.126 | F10: (robots + flete) × IVA
A11: Infraestructura del club
A12: Servidor edge de IA | B12: Fijo | C12: =Supuestos!$C$18 -> 1500 | D12: =Supuestos!$D$18 -> 2500 | E12: =Supuestos!$E$18 -> 4000 | F12: costo único
A13: Red WiFi, puntos de acceso y estaciones de carga | B13: Fijo | C13: =Supuestos!$C$19 -> 1000 | D13: =Supuestos!$D$19 -> 2000 | E13: =Supuestos!$E$19 -> 3500 | F13: costo único
A14: Software e integración
A15: Desarrollo e integración con sistemas del club | B15: Fijo | C15: =Supuestos!$C$21*Supuestos!$C$22*Supuestos!$C$23/Supuestos!$C$6 -> 17068.298 | D15: =Supuestos!$D$21*Supuestos!$D$22*Supuestos!$D$23/Supuestos!$D$6 -> 40458.189 | E15: =Supuestos!$E$21*Supuestos!$E$22*Supuestos!$E$23/Supuestos!$E$6 -> 94823.88 | F15: personas × meses × costo mensual ÷ TRM
A16: Puesta en marcha
A17: Mapeo SLAM del club, geo-fencing y pruebas en sitio | B17: Fijo | C17: =Supuestos!$C$25 -> 1000 | D17: =Supuestos!$D$25 -> 2000 | E17: =Supuestos!$E$25 -> 4000 | F17: costo único
A18: Privacidad de datos biométricos | B18: Fijo | C18: =Supuestos!$C$26/Supuestos!$C$6 -> 1580.398 | D18: =Supuestos!$D$26/Supuestos!$D$6 -> 3160.796 | E18: =Supuestos!$E$26/Supuestos!$E$6 -> 6321.592 | F18: COP ÷ TRM
A19: Capacitación inicial del personal | B19: Fijo | C19: =Supuestos!$C$27/Supuestos!$C$6 -> 632.1592 | D19: =Supuestos!$D$27/Supuestos!$D$6 -> 1264.3184 | E19: =Supuestos!$E$27/Supuestos!$E$6 -> 1896.4776 | F19: COP ÷ TRM
A20: Supervisión humana durante el piloto | B20: Fijo | C20: =Supuestos!$C$29*Supuestos!$C$34*Supuestos!$C$28*Supuestos!$C$32/Supuestos!$C$33/Supuestos!$C$6 -> 1540.8881 | D20: =Supuestos!$D$29*Supuestos!$D$34*Supuestos!$D$28*Supuestos!$D$32/Supuestos!$D$33/Supuestos!$D$6 -> 2696.5541 | E20: =Supuestos!$E$29*Supuestos!$E$34*Supuestos!$E$28*Supuestos!$E$32/Supuestos!$E$33/Supuestos!$E$6 -> 4741.194 | F20: h/día × días × meses × costo hora ÷ TRM
A21: Subtotal inversión | C21: =C5+C6+C7+C9+C10+C12+C13+C15+C17+C18+C19+C20 -> 63905.904 | D21: =D5+D6+D7+D9+D10+D12+D13+D15+D17+D18+D19+D20 -> 102116.23 | E21: =E5+E6+E7+E9+E10+E12+E13+E15+E17+E18+E19+E20 -> 193176.67 | F21: Suma de conceptos (sin duplicar el subtotal de robots)
A22: Contingencia | C22: =C21*Supuestos!$C$30 -> 6390.5904 | D22: =D21*Supuestos!$D$30 -> 12764.529 | E22: =E21*Supuestos!$E$30 -> 28976.501 | F22: subtotal × % contingencia
A23: TOTAL INVERSIÓN INICIAL (USD) | C23: =C21+C22 -> 70296.494 | D23: =D21+D22 -> 114880.76 | E23: =E21+E22 -> 222153.17 | F23: subtotal + contingencia
A25: Apoyos de cálculo (para el escalamiento de la flota)
A26: Costo de cada X2 adicional | C26: =(Supuestos!$C$11+Supuestos!$C$13*Supuestos!$C$14)*(1+Supuestos!$C$15)*(1+Supuestos!$C$16)*(1+Supuestos!$C$30) -> 35185.92 | D26: =(Supuestos!$D$11+Supuestos!$D$13*Supuestos!$D$14)*(1+Supuestos!$D$15)*(1+Supuestos!$D$16)*(1+Supuestos!$D$30) -> 43439.492 | E26: =(Supuestos!$E$11+Supuestos!$E$13*Supuestos!$E$14)*(1+Supuestos!$E$15)*(1+Supuestos!$E$16)*(1+Supuestos!$E$30) -> 72388.929 | F26: (precio + baterías) × (1+flete) × (1+IVA) × (1+contingencia)
A27: Costo de cada D1 adicional | C27: =Supuestos!$C$12*(1+Supuestos!$C$15)*(1+Supuestos!$C$16)*(1+Supuestos!$C$30) -> 8356.656 | D27: =Supuestos!$D$12*(1+Supuestos!$D$15)*(1+Supuestos!$D$16)*(1+Supuestos!$D$30) -> 10601.427 | E27: =Supuestos!$E$12*(1+Supuestos!$E$15)*(1+Supuestos!$E$16)*(1+Supuestos!$E$30) -> 12588.626 | F27: precio × (1+flete) × (1+IVA) × (1+contingencia)
A28: Parte fija (no cambia con la flota) | C28: =C23-Supuestos!$C$7*C26-Supuestos!$C$8*C27 -> 26753.918 | D28: =D23-Supuestos!$D$7*D26-Supuestos!$D$8*D27 -> 60839.84 | E28: =E23-Supuestos!$E$7*E26-Supuestos!$E$8*E27 -> 137175.62 | F28: total − robots × costo por robot
A29: Base de hardware para mantenimiento y seguro | C29: =C8+C12+C13 -> 34180 | D29: =D8+D12+D13 -> 41197 | E29: =E8+E12+E13 -> 61496 | F29: robots + servidor edge + red

Sheet C_Operacion
A1: Bloque C — Operación anual (OPEX, USD por año)
A3: Concepto | B3: Tipo | C3: Bajo | D3: Base | E3: Alto | F3: Cálculo
A4: Nube, base de datos y almacenamiento | B4: Fijo | C4: =Supuestos!$C$36*12 -> 600 | D4: =Supuestos!$D$36*12 -> 1800 | E4: =Supuestos!$E$36*12 -> 4800 | F4: USD/mes × 12
A5: APIs de voz e IA conversacional | B5: Por robot | C5: =Supuestos!$C$7*Supuestos!$C$37*12 -> 600 | D5: =Supuestos!$D$7*Supuestos!$D$37*12 -> 1800 | E5: =Supuestos!$E$7*Supuestos!$E$37*12 -> 4800 | F5: X2 × USD/mes × 12
A6: Mantenimiento y repuestos | B6: Por robot | C6: =B_Inversion!C29*Supuestos!$C$38 -> 2734.4 | D6: =B_Inversion!D29*Supuestos!$D$38 -> 4943.64 | E6: =B_Inversion!E29*Supuestos!$E$38 -> 9224.4 | F6: base de hardware × %
A7: Seguro todo riesgo de los equipos | B7: Por robot | C7: =B_Inversion!C29*Supuestos!$C$41 -> 512.7 | D7: =B_Inversion!D29*Supuestos!$D$41 -> 823.94 | E7: =B_Inversion!E29*Supuestos!$E$41 -> 1844.88 | F7: base de hardware × %
A8: Soporte y evolución del software | B8: Fijo | C8: =Supuestos!$C$39*Supuestos!$C$23*12/Supuestos!$C$6 -> 5689.4328 | D8: =Supuestos!$D$39*Supuestos!$D$23*12/Supuestos!$D$6 -> 15171.821 | E8: =Supuestos!$E$39*Supuestos!$E$23*12/Supuestos!$E$6 -> 37929.552 | F8: FTE × costo mensual × 12 ÷ TRM
A9: Supervisión humana de excepciones | B9: Fijo | C9: =Supuestos!$C$40*Supuestos!$C$34*12*Supuestos!$C$32/Supuestos!$C$33/Supuestos!$C$6 -> 1540.8881 | D9: =Supuestos!$D$40*Supuestos!$D$34*12*Supuestos!$D$32/Supuestos!$D$33/Supuestos!$D$6 -> 3595.4055 | E9: =Supuestos!$E$40*Supuestos!$E$34*12*Supuestos!$E$32/Supuestos!$E$33/Supuestos!$E$6 -> 7111.791 | F9: h/día × días × 12 × costo hora ÷ TRM
A10: Recapacitación anual | B10: Fijo | C10: =Supuestos!$C$42/Supuestos!$C$6 -> 316.0796 | D10: =Supuestos!$D$42/Supuestos!$D$6 -> 632.1592 | E10: =Supuestos!$E$42/Supuestos!$E$6 -> 948.2388 | F10: COP ÷ TRM
A11: Energía eléctrica | B11: Por robot | C11: =(Supuestos!$C$7+Supuestos!$C$8)*Supuestos!$C$43 -> 100 | D11: =(Supuestos!$D$7+Supuestos!$D$8)*Supuestos!$D$43 -> 200 | E11: =(Supuestos!$E$7+Supuestos!$E$8)*Supuestos!$E$43 -> 300 | F11: robots × USD/año
A12: Subtotal operación | C12: =SUM(C4:C11) -> 12093.5 | D12: =SUM(D4:D11) -> 28966.966 | E12: =SUM(E4:E11) -> 66958.862 | F12: Suma
A13: Contingencia | C13: =C12*Supuestos!$C$30 -> 1209.35 | D13: =D12*Supuestos!$D$30 -> 3620.8707 | E13: =E12*Supuestos!$E$30 -> 10043.829 | F13: subtotal × %
A14: TOTAL OPERACIÓN ANUAL (USD/año) | C14: =C12+C13 -> 13302.851 | D14: =D12+D13 -> 32587.836 | E14: =E12+E13 -> 77002.691 | F14: subtotal + contingencia
A16: Apoyos de cálculo (para el escalamiento de la flota)
A17: Costo anual de cada X2 adicional | C17: =(Supuestos!$C$37*12+(Supuestos!$C$11+Supuestos!$C$13*Supuestos!$C$14)*(Supuestos!$C$38+Supuestos!$C$41)+Supuestos!$C$43)*(1+Supuestos!$C$30) -> 3390.2 | D17: =(Supuestos!$D$37*12+(Supuestos!$D$11+Supuestos!$D$13*Supuestos!$D$14)*(Supuestos!$D$38+Supuestos!$D$41)+Supuestos!$D$43)*(1+Supuestos!$D$30) -> 6783.435 | E17: =(Supuestos!$E$37*12+(Supuestos!$E$11+Supuestos!$E$13*Supuestos!$E$14)*(Supuestos!$E$38+Supuestos!$E$41)+Supuestos!$E$43)*(1+Supuestos!$E$30) -> 15213.879 | F17: (IA + mantenimiento + seguro + energía) × (1+contingencia)
A18: Costo anual de cada D1 adicional | C18: =(Supuestos!$C$12*(Supuestos!$C$38+Supuestos!$C$41)+Supuestos!$C$43)*(1+Supuestos!$C$30) -> 690.36 | D18: =(Supuestos!$D$12*(Supuestos!$D$38+Supuestos!$D$41)+Supuestos!$D$43)*(1+Supuestos!$D$30) -> 1246.3425 | E18: =(Supuestos!$E$12*(Supuestos!$E$38+Supuestos!$E$41)+Supuestos!$E$43)*(1+Supuestos!$E$30) -> 1828.293 | F18: (mantenimiento + seguro + energía) × (1+contingencia)
A19: Parte fija (no cambia con la flota) | C19: =C14-Supuestos!$C$7*C17-Supuestos!$C$8*C18 -> 9222.2905 | D19: =D14-Supuestos!$D$7*D17-Supuestos!$D$8*D18 -> 24558.059 | E19: =E14-Supuestos!$E$7*E17-Supuestos!$E$8*E18 -> 59960.519 | F19: total − robots × costo por robot

Sheet Valor_Impacto
A1: Hipótesis de impacto (por validar en el piloto)
A2: Tiempo liberado para atención especial y excepciones. NO equivale a reducción de personal ni a ahorro financiero.
A4: Indicador | B4: Unidad | C4: Bajo | D4: Base | E4: Alto | F4: Cálculo
A5: Interacciones atendidas por Hugo y Dogo | B5: por mes | C5: =Supuestos!$C$47*Supuestos!$C$34 -> 2080 | D5: =Supuestos!$D$47*Supuestos!$D$34 -> 3120 | E5: =Supuestos!$E$47*Supuestos!$E$34 -> 4800 | F5: consultas/día × días
A6: Horas humanas en consultas rutinarias (hoy) | B6: horas / mes | C6: =C5*Supuestos!$C$48/60 -> 69.333333 | D6: =D5*Supuestos!$D$48/60 -> 156 | E6: =E5*Supuestos!$E$48/60 -> 320 | F6: interacciones × minutos ÷ 60
A7: Horas liberadas con la meta de reducción | B7: horas / mes | C7: =C6*Supuestos!$C$49 -> 20.8 | D7: =D6*Supuestos!$D$49 -> 46.8 | E7: =E6*Supuestos!$E$49 -> 96 | F7: horas × % meta
A8: Valor del tiempo liberado | B8: USD / mes | C8: =C7*Supuestos!$C$32/Supuestos!$C$33/Supuestos!$C$6 -> 102.72587 | D8: =D7*Supuestos!$D$32/Supuestos!$D$33/Supuestos!$D$6 -> 269.65541 | E8: =E7*Supuestos!$E$32/Supuestos!$E$33/Supuestos!$E$6 -> 632.1592 | F8: horas × costo hora ÷ TRM
A9: Costo mensual de Hugo y Dogo (amortizado) | B9: USD / mes | C9: =B_Inversion!C23/Supuestos!$C$9+C_Operacion!C14/12 -> 3061.2513 | D9: =B_Inversion!D23/Supuestos!$D$9+C_Operacion!D14/12 -> 5906.7852 | E9: =B_Inversion!E23/Supuestos!$E$9+C_Operacion!E14/12 -> 12587.812 | F9: inversión ÷ vida útil + operación ÷ 12
A10: Costo por interacción | B10: USD | C10: =IF(C5=0,0,C9/C5) -> 1.4717554 | D10: =IF(D5=0,0,D9/D5) -> 1.8932004 | E10: =IF(E5=0,0,E9/E5) -> 2.6224609 | F10: costo mensual ÷ interacciones
A12: Lectura: el valor del tiempo liberado no busca 'pagar' el robot; muestra cuánta capacidad de recepción queda disponible para atención especial. El caso de negocio se apoya en experiencia, coordinación y seguridad.
